package exception_handling;

public class TryCatchTest2 {

	public static void main(String[] args) {
		System.out.println("Exception Handling Test Initiated");
		try
		{
			int[] a=new int[2];
			int i=1/0;
		}
		catch(ArithmeticException e){
			System.out.println("alert :Your Input is Wrong"+ e.getMessage());
		}
		System.out.println("Exception Hanling Test Completed");
	}
}
